<sdf version='1.11'>
  <model name='udemy_robot'>
    <link name='base_link'>
      <inertial>
        <pose>-0.018181818181818181 0 0.1863636363636364 0 0 0</pose>
        <mass>5.5</mass>
        <inertia>
          <ixx>0.17739393939393941</ixx>
          <ixy>0</ixy>
          <ixz>-0.013636363636363639</ixz>
          <iyy>0.1122424242424242</iyy>
          <iyz>0</iyz>
          <izz>0.23534848484848481</izz>
        </inertia>
      </inertial>
      <collision name='base_link_fixed_joint_lump__body_collision'>
        <pose>0 0 0.20000000000000001 0 0 0</pose>
        <geometry>
          <box>
            <size>0.59999999999999998 0.40000000000000002 0.20000000000000001</size>
          </box>
        </geometry>
      </collision>
      <collision name='base_link_fixed_joint_lump__caster_wheel_collision_1'>
        <pose>-0.20000000000000001 0 0.050000000000000003 0 0 0</pose>
        <geometry>
          <sphere>
            <radius>0.050000000000000003</radius>
          </sphere>
        </geometry>
      </collision>
      <visual name='base_link_fixed_joint_lump__body_visual'>
        <pose>0 0 0.20000000000000001 0 0 0</pose>
        <geometry>
          <box>
            <size>0.59999999999999998 0.40000000000000002 0.20000000000000001</size>
          </box>
        </geometry>
        <material>
          <diffuse>0 0 1 1</diffuse>
          <ambient>0 0 1 1</ambient>
        </material>
      </visual>
      <visual name='base_link_fixed_joint_lump__caster_wheel_visual_1'>
        <pose>-0.20000000000000001 0 0.050000000000000003 0 0 0</pose>
        <geometry>
          <sphere>
            <radius>0.050000000000000003</radius>
          </sphere>
        </geometry>
        <material>
          <diffuse>0.625 0.625 0.625 1</diffuse>
          <ambient>0.625 0.625 0.625 1</ambient>
        </material>
      </visual>
    </link>
    <joint name='left_wheel_joint' type='revolute'>
      <pose relative_to='base_link'>0.14999999999999999 -0.20000000000000001 0.10000000000000001 0 0 0</pose>
      <parent>base_link</parent>
      <child>left_wheel</child>
      <axis>
        <xyz>0 1 0</xyz>
        <limit>
          <lower>-inf</lower>
          <upper>inf</upper>
        </limit>
        <dynamics>
          <spring_reference>0</spring_reference>
          <spring_stiffness>0</spring_stiffness>
        </dynamics>
      </axis>
    </joint>
    <link name='left_wheel'>
      <pose relative_to='left_wheel_joint'>0 0 0 0 0 0</pose>
      <inertial>
        <pose>0 -0.025000000000000001 0 1.5707963267948959 0 0</pose>
        <mass>1</mass>
        <inertia>
          <ixx>0.0027083333333333339</ixx>
          <ixy>0</ixy>
          <ixz>0</ixz>
          <iyy>0.0027083333333333339</iyy>
          <iyz>0</iyz>
          <izz>0.005000000000000001</izz>
        </inertia>
      </inertial>
      <collision name='left_wheel_collision'>
        <pose>0 -0.025000000000000001 0 1.5707963267948959 0 0</pose>
        <geometry>
          <cylinder>
            <length>0.050000000000000003</length>
            <radius>0.10000000000000001</radius>
          </cylinder>
        </geometry>
      </collision>
      <visual name='left_wheel_visual'>
        <pose>0 -0.025000000000000001 0 1.5707963267948959 0 0</pose>
        <geometry>
          <cylinder>
            <length>0.050000000000000003</length>
            <radius>0.10000000000000001</radius>
          </cylinder>
        </geometry>
        <material>
          <diffuse>0.625 0.625 0.625 1</diffuse>
          <ambient>0.625 0.625 0.625 1</ambient>
        </material>
      </visual>
    </link>
    <joint name='right_wheel_joint' type='revolute'>
      <pose relative_to='base_link'>0.14999999999999999 0.20000000000000001 0.10000000000000001 0 0 0</pose>
      <parent>base_link</parent>
      <child>right_wheel</child>
      <axis>
        <xyz>0 1 0</xyz>
        <limit>
          <lower>-inf</lower>
          <upper>inf</upper>
        </limit>
        <dynamics>
          <spring_reference>0</spring_reference>
          <spring_stiffness>0</spring_stiffness>
        </dynamics>
      </axis>
    </joint>
    <link name='right_wheel'>
      <pose relative_to='right_wheel_joint'>0 0 0 0 0 0</pose>
      <inertial>
        <pose>0 0.025000000000000001 0 -1.5707963267948959 0 0</pose>
        <mass>1</mass>
        <inertia>
          <ixx>0.0027083333333333339</ixx>
          <ixy>0</ixy>
          <ixz>0</ixz>
          <iyy>0.0027083333333333339</iyy>
          <iyz>0</iyz>
          <izz>0.005000000000000001</izz>
        </inertia>
      </inertial>
      <collision name='right_wheel_collision'>
        <pose>0 0.025000000000000001 0 -1.5707963267948959 0 0</pose>
        <geometry>
          <cylinder>
            <length>0.050000000000000003</length>
            <radius>0.10000000000000001</radius>
          </cylinder>
        </geometry>
      </collision>
      <visual name='right_wheel_visual'>
        <pose>0 0.025000000000000001 0 -1.5707963267948959 0 0</pose>
        <geometry>
          <cylinder>
            <length>0.050000000000000003</length>
            <radius>0.10000000000000001</radius>
          </cylinder>
        </geometry>
        <material>
          <diffuse>0.625 0.625 0.625 1</diffuse>
          <ambient>0.625 0.625 0.625 1</ambient>
        </material>
      </visual>
    </link>
    <frame name='caster_wheel_joint' attached_to='body'>
      <pose>-0.20000000000000001 0 -0.050000000000000003 0 0 0</pose>
    </frame>
    <frame name='caster_wheel' attached_to='caster_wheel_joint'>
      <pose>0 0 0 0 0 0</pose>
    </frame>
    <frame name='base_link_to_body' attached_to='base_link'>
      <pose>0 0 0.10000000000000001 0 0 0</pose>
    </frame>
    <frame name='body' attached_to='base_link_to_body'>
      <pose>0 0 0 0 0 0</pose>
    </frame>
  </model>
</sdf>
